Workbook

Sheet 0. 표지
K3: 문서번호 | L3: CHECKBANG-CA-2026-002
K4: 작성자 | L4: 취약점진단팀
K5: 보안등급 | L5: Confidential
K6: Ver | L6: ver 1.0
B11: "Check방" 취약점 진단
B13: Unix 서버 이행점검 결과
B18: 46189

Sheet 1. 진단 대상
B1: ※ 진단 대상 리스트 - 서버 1대 (Unix 1대)
B2: 순번 | C2: 진단 대상 | G2: 비고
C3: Hostname | D3: IP Address | E3: 버전정보 | F3: 용도
B4: Linux
B5: 1 | C5: ip-10-0-9-57.ec2.internal | D5: 10.0.9.57 | E5: amazon-linux-2023 | F5: WAS

Sheet 2-1. 요약결과(그래프)
F2: 항목별 양호 비율
B4: 진단 도메인 | C4: 평균 점수
B5: ='2-2. 요약 진단결과(Unix)'!B6 -> 1. 계정 관리 | C5: ='2-2. 요약 진단결과(Unix)'!H6 -> 1
B6: ='2-2. 요약 진단결과(Unix)'!B19 -> 2. 파일 및 디렉토리 관리 | C6: ='2-2. 요약 진단결과(Unix)'!H19 -> 1
B7: ='2-2. 요약 진단결과(Unix)'!B39 -> 3. 서비스 관리 | C7: ='2-2. 요약 진단결과(Unix)'!H39 -> 1
B8: ='2-2. 요약 진단결과(Unix)'!B69 -> 4. 패치 관리 | C8: ='2-2. 요약 진단결과(Unix)'!H69 -> 0
B9: ='2-2. 요약 진단결과(Unix)'!B70 -> 5. 로그 관리 | C9: ='2-2. 요약 진단결과(Unix)'!H70 -> 1
F16: 양호 / 취약 / N/A 비율
B18: 상태 | C18: 개수
B19: 양호 | C19: =SUM('2-2. 요약 진단결과(Unix)'!J:J) -> 54
B20: 취약 | C20: =SUM('2-2. 요약 진단결과(Unix)'!K:K) -> 1
B21: N/A | C21: =SUM('2-2. 요약 진단결과(Unix)'!L:L) -> 12
F32: 영역별 취약 수
B34: 영역 | C34: 취약 수
B35: 계정 관리 | C35: =SUM('2-2. 요약 진단결과(Unix)'!K6:K18) -> 0
B36: 파일 및 디렉토리 관리 | C36: =SUM('2-2. 요약 진단결과(Unix)'!K19:K38) -> 0
B37: 서비스 관리 | C37: =SUM('2-2. 요약 진단결과(Unix)'!K39:K68) -> 0
B38: 패치 관리 | C38: =SUM('2-2. 요약 진단결과(Unix)'!K69) -> 1
B39: 로그 관리 | C39: =SUM('2-2. 요약 진단결과(Unix)'!K70:K72) -> 0

Sheet 2-2. 요약 진단결과(Unix)
B2: Unix 취약점 진단 요약결과(67항목)
B3: 진단항목 | C3: No. | D3: 세부 진단항목 | E3: 중 요 도 | F3: 1
F4: =VLOOKUP(F$3,'1. 진단 대상'!$B5:$F$5,2,FALSE()) -> ip-10-0-9-57.ec2.internal
F5: =VLOOKUP(F$3,'1. 진단 대상'!$B5:$F$5,3,FALSE()) -> 10.0.9.57 | H5: 영역별점수 | I5: 점수 | J5: 양호 | K5: 취약 | L5: N/A
B6: 1. 계정 관리 | C6: U-01 | D6: root 계정 원격 접속 제한 | E6: 상 | F6: 양호 | H6: =IF(COUNTIF(I6:I18,"N/A")=COUNTA(I6:I18),"N/A",AVERAGE(I6:I18)) -> 1 | I6: =IF(COUNTIF($F6:$F6,"N/A")=COUNTA($F6:$F6),"N/A",$J6/(COUNTA($F6:$F6)-$L6)) -> 1 | J6: =COUNTIF($F6:$F6,"양호") -> 1 | K6: =COUNTIF($F6:$F6,"취약") -> 0 | L6: =COUNTIF($F6:$F6,"N/A") -> 0
C7: U-02 | D7: 비밀번호 관리정책 설정 | E7: 상 | F7: 양호 | I7: =IF(COUNTIF($F7:$F7,"N/A")=COUNTA($F7:$F7),"N/A",$J7/(COUNTA($F7:$F7)-$L7)) -> 1 | J7: =COUNTIF($F7:$F7,"양호") -> 1 | K7: =COUNTIF($F7:$F7,"취약") -> 0 | L7: =COUNTIF($F7:$F7,"N/A") -> 0
C8: U-03 | D8: 계정 잠금 임계값 설정 | E8: 상 | F8: 양호 | I8: =IF(COUNTIF($F8:$F8,"N/A")=COUNTA($F8:$F8),"N/A",$J8/(COUNTA($F8:$F8)-$L8)) -> 1 | J8: =COUNTIF($F8:$F8,"양호") -> 1 | K8: =COUNTIF($F8:$F8,"취약") -> 0 | L8: =COUNTIF($F8:$F8,"N/A") -> 0
C9: U-04 | D9: 비밀번호 파일 보호 | E9: 상 | F9: 양호 | I9: =IF(COUNTIF($F9:$F9,"N/A")=COUNTA($F9:$F9),"N/A",$J9/(COUNTA($F9:$F9)-$L9)) -> 1 | J9: =COUNTIF($F9:$F9,"양호") -> 1 | K9: =COUNTIF($F9:$F9,"취약") -> 0 | L9: =COUNTIF($F9:$F9,"N/A") -> 0
C10: U-05 | D10: root 이외의 UID가 '0' 금지 | E10: 상 | F10: 양호 | I10: =IF(COUNTIF($F10:$F10,"N/A")=COUNTA($F10:$F10),"N/A",$J10/(COUNTA($F10:$F10)-$L10)) -> 1 | J10: =COUNTIF($F10:$F10,"양호") -> 1 | K10: =COUNTIF($F10:$F10,"취약") -> 0 | L10: =COUNTIF($F10:$F10,"N/A") -> 0
C11: U-06 | D11: 사용자 계정 su 기능 제한 | E11: 상 | F11: 양호 | I11: =IF(COUNTIF($F11:$F11,"N/A")=COUNTA($F11:$F11),"N/A",$J11/(COUNTA($F11:$F11)-$L11)) -> 1 | J11: =COUNTIF($F11:$F11,"양호") -> 1 | K11: =COUNTIF($F11:$F11,"취약") -> 0 | L11: =COUNTIF($F11:$F11,"N/A") -> 0
C12: U-07 | D12: 불필요한 계정 제거 | E12: 하 | F12: 양호 | I12: =IF(COUNTIF($F12:$F12,"N/A")=COUNTA($F12:$F12),"N/A",$J12/(COUNTA($F12:$F12)-$L12)) -> 1 | J12: =COUNTIF($F12:$F12,"양호") -> 1 | K12: =COUNTIF($F12:$F12,"취약") -> 0 | L12: =COUNTIF($F12:$F12,"N/A") -> 0
C13: U-08 | D13: 관리자 그룹에 최소한의 계정 포함 | E13: 중 | F13: 양호 | I13: =IF(COUNTIF($F13:$F13,"N/A")=COUNTA($F13:$F13),"N/A",$J13/(COUNTA($F13:$F13)-$L13)) -> 1 | J13: =COUNTIF($F13:$F13,"양호") -> 1 | K13: =COUNTIF($F13:$F13,"취약") -> 0 | L13: =COUNTIF($F13:$F13,"N/A") -> 0
C14: U-09 | D14: 계정이 존재하지 않는 GID 금지 | E14: 하 | F14: 양호 | I14: =IF(COUNTIF($F14:$F14,"N/A")=COUNTA($F14:$F14),"N/A",$J14/(COUNTA($F14:$F14)-$L14)) -> 1 | J14: =COUNTIF($F14:$F14,"양호") -> 1 | K14: =COUNTIF($F14:$F14,"취약") -> 0 | L14: =COUNTIF($F14:$F14,"N/A") -> 0
C15: U-10 | D15: 동일한 UID 금지 | E15: 중 | F15: 양호 | I15: =IF(COUNTIF($F15:$F15,"N/A")=COUNTA($F15:$F15),"N/A",$J15/(COUNTA($F15:$F15)-$L15)) -> 1 | J15: =COUNTIF($F15:$F15,"양호") -> 1 | K15: =COUNTIF($F15:$F15,"취약") -> 0 | L15: =COUNTIF($F15:$F15,"N/A") -> 0
C16: U-11 | D16: 사용자 Shell 점검 | E16: 하 | F16: 양호 | I16: =IF(COUNTIF($F16:$F16,"N/A")=COUNTA($F16:$F16),"N/A",$J16/(COUNTA($F16:$F16)-$L16)) -> 1 | J16: =COUNTIF($F16:$F16,"양호") -> 1 | K16: =COUNTIF($F16:$F16,"취약") -> 0 | L16: =COUNTIF($F16:$F16,"N/A") -> 0
C17: U-12 | D17: 세션 종료 시간 설정 | E17: 하 | F17: 양호 | I17: =IF(COUNTIF($F17:$F17,"N/A")=COUNTA($F17:$F17),"N/A",$J17/(COUNTA($F17:$F17)-$L17)) -> 1 | J17: =COUNTIF($F17:$F17,"양호") -> 1 | K17: =COUNTIF($F17:$F17,"취약") -> 0 | L17: =COUNTIF($F17:$F17,"N/A") -> 0
C18: U-13 | D18: 안전한 비밀번호 암호화 알고리즘 사용 | E18: 중 | F18: 양호 | I18: =IF(COUNTIF($F18:$F18,"N/A")=COUNTA($F18:$F18),"N/A",$J18/(COUNTA($F18:$F18)-$L18)) -> 1 | J18: =COUNTIF($F18:$F18,"양호") -> 1 | K18: =COUNTIF($F18:$F18,"취약") -> 0 | L18: =COUNTIF($F18:$F18,"N/A") -> 0
B19: 2. 파일 및 디렉토리 관리 | C19: U-14 | D19: root 홈, 패스 디렉터리 권한 및 패스 설정 | E19: 상 | F19: 양호 | H19: =IF(COUNTIF(I19:I38,"N/A")=COUNTA(I19:I38),"N/A",AVERAGE(I19:I38)) -> 1 | I19: =IF(COUNTIF($F19:$F19,"N/A")=COUNTA($F19:$F19),"N/A",$J19/(COUNTA($F19:$F19)-$L19)) -> 1 | J19: =COUNTIF($F19:$F19,"양호") -> 1 | K19: =COUNTIF($F19:$F19,"취약") -> 0 | L19: =COUNTIF($F19:$F19,"N/A") -> 0
C20: U-15 | D20: 파일 및 디렉터리 소유자 설정 | E20: 상 | F20: 양호 | I20: =IF(COUNTIF($F20:$F20,"N/A")=COUNTA($F20:$F20),"N/A",$J20/(COUNTA($F20:$F20)-$L20)) -> 1 | J20: =COUNTIF($F20:$F20,"양호") -> 1 | K20: =COUNTIF($F20:$F20,"취약") -> 0 | L20: =COUNTIF($F20:$F20,"N/A") -> 0
C21: U-16 | D21: /etc/passwd 파일 소유자 및 권한 설정 | E21: 상 | F21: 양호 | I21: =IF(COUNTIF($F21:$F21,"N/A")=COUNTA($F21:$F21),"N/A",$J21/(COUNTA($F21:$F21)-$L21)) -> 1 | J21: =COUNTIF($F21:$F21,"양호") -> 1 | K21: =COUNTIF($F21:$F21,"취약") -> 0 | L21: =COUNTIF($F21:$F21,"N/A") -> 0
C22: U-17 | D22: 시스템 시작 스크립트 권한 설정 | E22: 상 | F22: 양호 | I22: =IF(COUNTIF($F22:$F22,"N/A")=COUNTA($F22:$F22),"N/A",$J22/(COUNTA($F22:$F22)-$L22)) -> 1 | J22: =COUNTIF($F22:$F22,"양호") -> 1 | K22: =COUNTIF($F22:$F22,"취약") -> 0 | L22: =COUNTIF($F22:$F22,"N/A") -> 0
C23: U-18 | D23: /etc/shadow 파일 소유자 및 권한 설정 | E23: 상 | F23: 양호 | I23: =IF(COUNTIF($F23:$F23,"N/A")=COUNTA($F23:$F23),"N/A",$J23/(COUNTA($F23:$F23)-$L23)) -> 1 | J23: =COUNTIF($F23:$F23,"양호") -> 1 | K23: =COUNTIF($F23:$F23,"취약") -> 0 | L23: =COUNTIF($F23:$F23,"N/A") -> 0
C24: U-19 | D24: /etc/hosts 파일 소유자 및 권한 설정 | E24: 상 | F24: 양호 | I24: =IF(COUNTIF($F24:$F24,"N/A")=COUNTA($F24:$F24),"N/A",$J24/(COUNTA($F24:$F24)-$L24)) -> 1 | J24: =COUNTIF($F24:$F24,"양호") -> 1 | K24: =COUNTIF($F24:$F24,"취약") -> 0 | L24: =COUNTIF($F24:$F24,"N/A") -> 0
C25: U-20 | D25: /etc/(x)inetd.conf 파일 소유자 및 권한 설정 | E25: 상 | F25: 양호 | I25: =IF(COUNTIF($F25:$F25,"N/A")=COUNTA($F25:$F25),"N/A",$J25/(COUNTA($F25:$F25)-$L25)) -> 1 | J25: =COUNTIF($F25:$F25,"양호") -> 1 | K25: =COUNTIF($F25:$F25,"취약") -> 0 | L25: =COUNTIF($F25:$F25,"N/A") -> 0
C26: U-21 | D26: /etc/(r)syslog.conf 파일 소유자 및 권한 설정 | E26: 상 | F26: 양호 | I26: =IF(COUNTIF($F26:$F26,"N/A")=COUNTA($F26:$F26),"N/A",$J26/(COUNTA($F26:$F26)-$L26)) -> 1 | J26: =COUNTIF($F26:$F26,"양호") -> 1 | K26: =COUNTIF($F26:$F26,"취약") -> 0 | L26: =COUNTIF($F26:$F26,"N/A") -> 0
C27: U-22 | D27: /etc/services 파일 소유자 및 권한 설정 | E27: 상 | F27: 양호 | I27: =IF(COUNTIF($F27:$F27,"N/A")=COUNTA($F27:$F27),"N/A",$J27/(COUNTA($F27:$F27)-$L27)) -> 1 | J27: =COUNTIF($F27:$F27,"양호") -> 1 | K27: =COUNTIF($F27:$F27,"취약") -> 0 | L27: =COUNTIF($F27:$F27,"N/A") -> 0
C28: U-23 | D28: SUID, SGID, Sticky bit 설정 파일 점검 | E28: 상 | F28: 양호 | I28: =IF(COUNTIF($F28:$F28,"N/A")=COUNTA($F28:$F28),"N/A",$J28/(COUNTA($F28:$F28)-$L28)) -> 1 | J28: =COUNTIF($F28:$F28,"양호") -> 1 | K28: =COUNTIF($F28:$F28,"취약") -> 0 | L28: =COUNTIF($F28:$F28,"N/A") -> 0
C29: U-24 | D29: 사용자, 시스템 환경변수 파일 소유자 및 권한 설정 | E29: 상 | F29: 양호 | I29: =IF(COUNTIF($F29:$F29,"N/A")=COUNTA($F29:$F29),"N/A",$J29/(COUNTA($F29:$F29)-$L29)) -> 1 | J29: =COUNTIF($F29:$F29,"양호") -> 1 | K29: =COUNTIF($F29:$F29,"취약") -> 0 | L29: =COUNTIF($F29:$F29,"N/A") -> 0
C30: U-25 | D30: world writable 파일 점검 | E30: 상 | F30: 양호 | I30: =IF(COUNTIF($F30:$F30,"N/A")=COUNTA($F30:$F30),"N/A",$J30/(COUNTA($F30:$F30)-$L30)) -> 1 | J30: =COUNTIF($F30:$F30,"양호") -> 1 | K30: =COUNTIF($F30:$F30,"취약") -> 0 | L30: =COUNTIF($F30:$F30,"N/A") -> 0
C31: U-26 | D31: /dev에 존재하지 않는 device 파일 점검 | E31: 상 | F31: 양호 | I31: =IF(COUNTIF($F31:$F31,"N/A")=COUNTA($F31:$F31),"N/A",$J31/(COUNTA($F31:$F31)-$L31)) -> 1 | J31: =COUNTIF($F31:$F31,"양호") -> 1 | K31: =COUNTIF($F31:$F31,"취약") -> 0 | L31: =COUNTIF($F31:$F31,"N/A") -> 0
... C38: U-33 | D38: 숨겨진 파일 및 디렉토리 검색 및 제거 | E38: 하 | F38: 양호 | I38: =IF(COUNTIF($F38:$F38,"N/A")=COUNTA($F38:$F38),"N/A",$J38/(COUNTA($F38:$F38)-$L38)) -> 1 | J38: =COUNTIF($F38:$F38,"양호") -> 1 | K38: =COUNTIF($F38:$F38,"취약") -> 0 | L38: =COUNTIF($F38:$F38,"N/A") -> 0
B39: 3. 서비스 관리 | C39: U-34 | D39: Finger 서비스 비활성화 | E39: 상 | F39: 양호 | H39: =IF(COUNTIF(I39:I68,"N/A")=COUNTA(I39:I68),"N/A",AVERAGE(I39:I68)) -> 1 | I39: =IF(COUNTIF($F39:$F39,"N/A")=COUNTA($F39:$F39),"N/A",$J39/(COUNTA($F39:$F39)-$L39)) -> 1 | J39: =COUNTIF($F39:$F39,"양호") -> 1 | K39: =COUNTIF($F39:$F39,"취약") -> 0 | L39: =COUNTIF($F39:$F39,"N/A") -> 0
C40: U-35 | D40: 공유 서비스에 대한 익명 접근 제한 설정 | E40: 상 | F40: 양호 | I40: =IF(COUNTIF($F40:$F40,"N/A")=COUNTA($F40:$F40),"N/A",$J40/(COUNTA($F40:$F40)-$L40)) -> 1 | J40: =COUNTIF($F40:$F40,"양호") -> 1 | K40: =COUNTIF($F40:$F40,"취약") -> 0 | L40: =COUNTIF($F40:$F40,"N/A") -> 0
C41: U-36 | D41: r 계열 서비스 비활성화 | E41: 상 | F41: 양호 | I41: =IF(COUNTIF($F41:$F41,"N/A")=COUNTA($F41:$F41),"N/A",$J41/(COUNTA($F41:$F41)-$L41)) -> 1 | J41: =COUNTIF($F41:$F41,"양호") -> 1 | K41: =COUNTIF($F41:$F41,"취약") -> 0 | L41: =COUNTIF($F41:$F41,"N/A") -> 0
C42: U-37 | D42: crontab 설정파일 권한 설정 미흡 | E42: 상 | F42: 양호 | I42: =IF(COUNTIF($F42:$F42,"N/A")=COUNTA($F42:$F42),"N/A",$J42/(COUNTA($F42:$F42)-$L42)) -> 1 | J42: =COUNTIF($F42:$F42,"양호") -> 1 | K42: =COUNTIF($F42:$F42,"취약") -> 0 | L42: =COUNTIF($F42:$F42,"N/A") -> 0
C43: U-38 | D43: DoS 공격에 취약한 서비스 비활성화 | E43: 상 | F43: 양호 | I43: =IF(COUNTIF($F43:$F43,"N/A")=COUNTA($F43:$F43),"N/A",$J43/(COUNTA($F43:$F43)-$L43)) -> 1 | J43: =COUNTIF($F43:$F43,"양호") -> 1 | K43: =COUNTIF($F43:$F43,"취약") -> 0 | L43: =COUNTIF($F43:$F43,"N/A") -> 0
C44: U-39 | D44: 불필요한 NFS 서비스 비활성화 | E44: 상 | F44: 양호 | I44: =IF(COUNTIF($F44:$F44,"N/A")=COUNTA($F44:$F44),"N/A",$J44/(COUNTA($F44:$F44)-$L44)) -> 1 | J44: =COUNTIF($F44:$F44,"양호") -> 1 | K44: =COUNTIF($F44:$F44,"취약") -> 0 | L44: =COUNTIF($F44:$F44,"N/A") -> 0
C45: U-40 | D45: NFS 접근 통제 | E45: 상 | F45: 양호 | I45: =IF(COUNTIF($F45:$F45,"N/A")=COUNTA($F45:$F45),"N/A",$J45/(COUNTA($F45:$F45)-$L45)) -> 1 | J45: =COUNTIF($F45:$F45,"양호") -> 1 | K45: =COUNTIF($F45:$F45,"취약") -> 0 | L45: =COUNTIF($F45:$F45,"N/A") -> 0
C46: U-41 | D46: 불필요한 automountd 제거 | E46: 상 | F46: 양호 | I46: =IF(COUNTIF($F46:$F46,"N/A")=COUNTA($F46:$F46),"N/A",$J46/(COUNTA($F46:$F46)-$L46)) -> 1 | J46: =COUNTIF($F46:$F46,"양호") -> 1 | K46: =COUNTIF($F46:$F46,"취약") -> 0 | L46: =COUNTIF($F46:$F46,"N/A") -> 0
C47: U-42 | D47: 불필요한 RPC 서비스 비활성화 | E47: 상 | F47: 양호 | I47: =IF(COUNTIF($F47:$F47,"N/A")=COUNTA($F47:$F47),"N/A",$J47/(COUNTA($F47:$F47)-$L47)) -> 1 | J47: =COUNTIF($F47:$F47,"양호") -> 1 | K47: =COUNTIF($F47:$F47,"취약") -> 0 | L47: =COUNTIF($F47:$F47,"N/A") -> 0
...

Sheet 3-1. 진단 결과(Unix)
B2: Unix 취약점 진단 상세결과(67항목)
B3: 진단항목 | C3: No. | D3: 세부 진단항목 | E3: 진단기준 | F3: 1 | G3: =VLOOKUP(F$3,'1. 진단 대상'!$B$5:$F$5,2,FALSE()) -> ip-10-0-9-57.ec2.internal | H3: =VLOOKUP(F$3,'1. 진단 대상'!$B$5:$F$5,2,FALSE) -> ip-10-0-9-57.ec2.internal
G4: =VLOOKUP(F$3,'1. 진단 대상'!$B$5:$F$5,3,FALSE()) -> 10.0.9.57 | H4: =VLOOKUP(F$3,'1. 진단 대상'!$B$5:$F$5,3,FALSE) -> 10.0.9.57
G5: 최초진단 | H5: 이행점검
B6: 1. 계정 관리 | C6: U-01 | D6: root 계정 원격 접속 제한 | E6: 양호: 원격터미널 서비스를 사용하지 않거나, 사용 시 root 직접 접속을 차단한 경우 취약: 원격터미널 서비스 사용 시 root 직접 접속을 허용한 경우 | F6: =_xlfn.XLOOKUP('2-2. 요약 진단결과(Unix)'!F6, '2-2. 요약 진단결과(Unix)'!$F$6:$F$72, '2-2. 요약 진단결과(Unix)'!$F$6:$F$72) -> 양호
C7: U-02 | D7: 비밀번호 관리정책 설정 | E7: 양호: 비밀번호 관리 정책이 설정된 경우 취약: 비밀번호 관리 정책이 설정되지 않은 경우 | F7: =_xlfn.XLOOKUP('2-2. 요약 진단결과(Unix)'!F7, '2-2. 요약 진단결과(Unix)'!$F$6:$F$72, '2-2. 요약 진단결과(Unix)'!$F$6:$F$72) -> 양호 | G7: ucredit: 대문자 (Uppercase) 제한 [1, 2] credit: 소문자 (Lowercase) 제한 [1, 2] dcredit: 숫자 (Digit) 제한 [1, 2] ocredit: 특수문자 (Other) 제한 [1, 2] 0 값은 비활성화
C8: U-03 | D8: 계정 잠금 임계값 설정 | E8: 양호: 계정 잠금 임계값이 10회 이하의 값으로 설정된 경우 취약: 계정 잠금 임계값이 설정되어 있지 않거나, 10회 이하의 값으로 설정되지 않은 경우 | F8: =_xlfn.XLOOKUP('2-2. 요약 진단결과(Unix)'!F8, '2-2. 요약 진단결과(Unix)'!$F$6:$F$72, '2-2. 요약 진단결과(Unix)'!$F$6:$F$72) -> 양호
C9: U-04 | D9: 비밀번호 파일 보호 | E9: 양호: 쉐도우 비밀번호를 사용하거나, 비밀번호를 암호화하여 저장하는 경우 취약: 쉐도우 비밀번호를 사용하지 않고, 비밀번호를 암호화하여 저장하지 않는 경우 | F9: =_xlfn.XLOOKUP('2-2. 요약 진단결과(Unix)'!F9, '2-2. 요약 진단결과(Unix)'!$F$6:$F$72, '2-2. 요약 진단결과(Unix)'!$F$6:$F$72) -> 양호
C10: U-05 | D10: root 이외의 UID가 '0' 금지 | E10: 양호: root 계정과 동일한 UID를 갖는 계정이 존재하지 않는 경우 취약: root 계정과 동일한 UID를 갖는 계정이 존재하는 경우 | F10: =_xlfn.XLOOKUP('2-2. 요약 진단결과(Unix)'!F10, '2-2. 요약 진단결과(Unix)'!$F$6:$F$72, '2-2. 요약 진단결과(Unix)'!$F$6:$F$72) -> 양호
C11: U-06 | D11: 사용자 계정 su 기능 제한 | E11: 양호: su 명령어를 특정 그룹에 속한 사용자만 사용하도록 제한된 경우 ※ 일반 사용자 계정 없이 root 계정만 사용하는 경우 취약: su 명령어를 모든 사용자가 사용하도록 설정된 경우 | F11: =_xlfn.XLOOKUP('2-2. 요약 진단결과(Unix)'!F11, '2-2. 요약 진단결과(Unix)'!$F$6:$F$72, '2-2. 요약 진단결과(Unix)'!$F$6:$F$72) -> 양호
C12: U-07 | D12: 불필요한 계정 제거 | E12: 양호: 불필요한 계정이 존재하지 않는 경우 취약: 불필요한 계정이 존재하는 경우 | F12: =_xlfn.XLOOKUP('2-2. 요약 진단결과(Unix)'!F12, '2-2. 요약 진단결과(Unix)'!$F$6:$F$72, '2-2. 요약 진단결과(Unix)'!$F$6:$F$72) -> 양호
C13: U-08 | D13: 관리자 그룹에 최소한의 계정 포함 | E13: 양호: 관리자 그룹에 불필요한 계정이 등록되어 있지 않은 경우 취약: 관리자 그룹에 불필요한 계정이 등록된 경우 | F13: =_xlfn.XLOOKUP('2-2. 요약 진단결과(Unix)'!F13, '2-2. 요약 진단결과(Unix)'!$F$6:$F$72, '2-2. 요약 진단결과(Unix)'!$F$6:$F$72) -> 양호
C14: U-09 | D14: 계정이 존재하지 않는 GID 금지 | E14: 양호: 시스템 관리나 운용에 불필요한 그룹이 제거된 경우 취약: 시스템 관리나 운용에 불필요한 그룹이 존재하는 경우 불필요한 그룹이 존재하는 경우 | F14: =_xlfn.XLOOKUP('2-2. 요약 진단결과(Unix)'!F14, '2-2. 요약 진단결과(Unix)'!$F$6:$F$72, '2-2. 요약 진단결과(Unix)'!$F$6:$F$72) -> 양호
C15: U-10 | D15: 동일한 UID 금지 | E15: 양호: 동일한 UID로 설정된 사용자 계정이 존재하지 않는 경우 취약: 동일한 UID로 설정된 사용자 계정이 존재하는 경우 | F15: =_xlfn.XLOOKUP('2-2. 요약 진단결과(Unix)'!F15, '2-2. 요약 진단결과(Unix)'!$F$6:$F$72, '2-2. 요약 진단결과(Unix)'!$F$6:$F$72) -> 양호
C16: U-11 | D16: 사용자 Shell 점검 | E16: 양호: 로그인이 필요하지 않은 계정에 /bin/false(/sbin/nologin) 쉘이 부여된 경우 취약: 로그인이 필요하지 않은 계정에 /bin/false(/sbin/nologin) 쉘이 부여되지 않은 경우 | F16: =_xlfn.XLOOKUP('2-2. 요약 진단결과(Unix)'!F16, '2-2. 요약 진단결과(Unix)'!$F$6:$F$72, '2-2. 요약 진단결과(Unix)'!$F$6:$F$72) -> 양호
C17: U-12 | D17: 세션 종료 시간 설정 | E17: 양호: Session Timeout이 600초(10분) 이하로 설정된 경우 취약: Session Timeout이 600초(10분) 이하로 설정되지 않은 경우 | F17: =_xlfn.XLOOKUP('2-2. 요약 진단결과(Unix)'!F17, '2-2. 요약 진단결과(Unix)'!$F$6:$F$72, '2-2. 요약 진단결과(Unix)'!$F$6:$F$72) -> 양호
C18: U-13 | D18: 안전한 비밀번호 암호화 알고리즘 사용 | E18: 양호: SHA-2 이상의 안전한 비밀번호 암호화 알고리즘을 사용하는 경우 취약: 취약한 비밀번호 암호화 알고리즘을 사용하는 경우 | F18: =_xlfn.XLOOKUP('2-2. 요약 진단결과(Unix)'!F18, '2-2. 요약 진단결과(Unix)'!$F$6:$F$72, '2-2. 요약 진단결과(Unix)'!$F$6:$F$72) -> 양호
B19: 2. 파일 및 디렉토리 관리 | C19: U-14 | D19: root 홈, 패스 디렉터리 권한 및 패스 설정 | E19: 양호: PATH 환경변수에 “.” 이 맨 앞이나 중간에 포함되지 않은 경우 취약: PATH 환경변수에 “.” 이 맨 앞이나 중간에 포함된 경우 | F19: =_xlfn.XLOOKUP('2-2. 요약 진단결과(Unix)'!F19, '2-2. 요약 진단결과(Unix)'!$F$6:$F$72, '2-2. 요약 진단결과(Unix)'!$F$6:$F$72) -> 양호
C20: U-15 | D20: 파일 및 디렉터리 소유자 설정 | E20: 양호: 소유자가 존재하지 않는 파일 및 디렉터리가 존재하지 않는 경우 취약: 소유자가 존재하지 않는 파일 및 디렉터리가 존재하는 경우 | F20: =_xlfn.XLOOKUP('2-2. 요약 진단결과(Unix)'!F20, '2-2. 요약 진단결과(Unix)'!$F$6:$F$72, '2-2. 요약 진단결과(Unix)'!$F$6:$F$72) -> 양호
C21: U-16 | D21: /etc/passwd 파일 소유자 및 권한 설정 | E21: 양호: /etc/passwd 파일의 소유자가 root이고, 권한이 644 이하인 경우 취약: /etc/passwd 파일의 소유자가 root가 아니거나, 권한이 644 이하가 아닌 경우 | F21: =_xlfn.XLOOKUP('2-2. 요약 진단결과(Unix)'!F21, '2-2. 요약 진단결과(Unix)'!$F$6:$F$72, '2-2. 요약 진단결과(Unix)'!$F$6:$F$72) -> 양호
C22: U-17 | D22: 시스템 시작 스크립트 권한 설정 | E22: 양호: 시스템 시작 스크립트 파일의 소유자가 root이고, 일반 사용자의 쓰기 권한이 제거된 경우 취약: 시스템 시작 스크립트 파일의 소유자가 root가 아니거나, 일반 사용자의 쓰기 권한이 부여된 경우 | F22: =_xlfn.XLOOKUP('2-2. 요약 진단결과(Unix)'!F22, '2-2. 요약 진단결과(Unix)'!$F$6:$F$72, '2-2. 요약 진단결과(Unix)'!$F$6:$F$72) -> 양호
C23: U-18 | D23: /etc/shadow 파일 소유자 및 권한 설정 | E23: 양호: /etc/shadow 파일의 소유자가 root이고, 권한이 400 이하인 경우 취약: /etc/shadow 파일의 소유자가 root가 아니거나, 권한이 400 이하가 아닌 경우 | F23: =_xlfn.XLOOKUP('2-2. 요약 진단결과(Unix)'!F23, '2-2. 요약 진단결과(Unix)'!$F$6:$F$72, '2-2. 요약 진단결과(Unix)'!$F$6:$F$72) -> 양호
C24: U-19 | D24: /etc/hosts 파일 소유자 및 권한 설정 | E24: 양호: /etc/hosts 파일의 소유자가 root이고, 권한이 644 이하인 경우 취약: /etc/hosts 파일의 소유자가 root가 아니거나, 권한이 644 이하가 아닌 경우 | F24: =_xlfn.XLOOKUP('2-2. 요약 진단결과(Unix)'!F24, '2-2. 요약 진단결과(Unix)'!$F$6:$F$72, '2-2. 요약 진단결과(Unix)'!$F$6:$F$72) -> 양호
C25: U-20 | D25: /etc/(x)inetd.conf 파일 소유자 및 권한 설정 | E25: 양호: /etc/(x)inetd.conf 파일의 소유자가 root이고, 권한이 600 이하인 경우 취약: /etc/(x)inetd.conf 파일의 소유자가 root가 아니거나, 권한이 600 이하가 아닌 경우 | F25: =_xlfn.XLOOKUP('2-2. 요약 진단결과(Unix)'!F25, '2-2. 요약 진단결과(Unix)'!$F$6:$F$72, '2-2. 요약 진단결과(Unix)'!$F$6:$F$72) -> 양호
C26: U-21 | D26: /etc/(r)syslog.conf 파일 소유자 및 권한 설정 | E26: 양호: /etc/(r)syslog.conf 파일의 소유자가 root(또는 bin, sys)이고, 권한이 640 이하인 경우 취약: /etc/(r)syslog.conf 파일의 소유자가 root(또는 bin, sys)가 아니거나, 권한이 640 이하가 아닌 경우 | F26: =_xlfn.XLOOKUP('2-2. 요약 진단결과(Unix)'!F26, '2-2. 요약 진단결과(Unix)'!$F$6:$F$72, '2-2. 요약 진단결과(Unix)'!$F$6:$F$72) -> 양호 | G26: /etc/(r)syslog 존재하지 않음
C27: U-22 | D27: /etc/services 파일 소유자 및 권한 설정 | E27: 양호: /etc/services 파일의 소유자가 root(또는 bin, sys)이고, 권한이 644 이하인 경우 취약: /etc/services 파일의 소유자가 root(또는 bin, sys)가 아니거나, 권한이 644 이하가 아닌 경우 | F27: =_xlfn.XLOOKUP('2-2. 요약 진단결과(Unix)'!F27, '2-2. 요약 진단결과(Unix)'!$F$6:$F$72, '2-2. 요약 진단결과(Unix)'!$F$6:$F$72) -> 양호
C28: U-23 | D28: SUID, SGID, Sticky bit 설정 파일 점검 | E28: 양호: 주요 실행 파일의 권한에 SUID와 SGID에 대한 설정이 부여되어 있지 않은 경우 취약: 주요 실행 파일의 권한에 SUID와 SGID에 대한 설정이 부여된 경우 | F28: =_xlfn.XLOOKUP('2-2. 요약 진단결과(Unix)'!F28, '2-2. 요약 진단결과(Unix)'!$F$6:$F$72, '2-2. 요약 진단결과(Unix)'!$F$6:$F$72) -> 양호 | G28: 일부 실행 파일에 SUID 및 SGID가 부여됨
C29: U-24 | D29: 사용자, 시스템 환경변수 파일 소유자 및 권한 설정 | E29: 양호: 홈 디렉터리 환경변수 파일 소유자가 root 또는 해당 계정으로 지정되어 있고, 홈 디렉터리 환경변수 파일에 root 계정과 소유자만 쓰기 권한이 부여된 경우 취약: 홈 디렉터리 환경변수 파일 소유자가 root 또는 해당 계정으로 지정되지 않거나, 홈 디렉터리 환경변수 파일에 root 계정과 소유자 외에 쓰기 권한이 부여된 경우 | F29: =_xlfn.XLOOKUP('2-2. 요약 진단결과(Unix)'!F29, '2-2. 요약 진단결과(Unix)'!$F$6:$F$72, '2-2. 요약 진단결과(Unix)'!$F$6:$F$72) -> 양호
C30: U-25 | D30: world writable 파일 점검 | E30: 양호: world writable 파일이 존재하지 않거나, 존재 시 설정 이유를 인지하고 있는 경우 취약: world writable 파일이 존재하나 설정 이유를 인지하지 못하고 있는 경우 | F30: =_xlfn.XLOOKUP('2-2. 요약 진단결과(Unix)'!F30, '2-2. 요약 진단결과(Unix)'!$F$6:$F$72, '2-2. 요약 진단결과(Unix)'!$F$6:$F$72) -> 양호 | G30: proc, sys, run을 제외하고 검색하는 경우에는 출력 결과 없음
C31: U-26 | D31: /dev에 존재하지 않는 device 파일 점검 | E31: 양호: /dev 디렉터리에 대한 파일 점검 후 존재하지 않는 device 파일을 제거한 경우 취약: /dev 디렉터리에 대한 파일 미점검 또는 존재하지 않는 device 파일을 방치한 경우 | F31: =_xlfn.XLOOKUP('2-2. 요약 진단결과(Unix)'!F31, '2-2. 요약 진단결과(Unix)'!$F$6:$F$72, '2-2. 요약 진단결과(Unix)'!$F$6:$F$72) -> 양호
C32: U-27 | D32: $HOME/.rhosts, hosts.equiv 사용 금지 | E32: 양호: rlogin, rsh, rexec 서비스를 사용하지 않거나, 사용 시 아래와 같은 설정이 적용된 경우 1. /etc/hosts.equiv 및 $HOME/.rhosts 파일 소유자가 root 또는 해당 계정인 경우 2. /etc/hosts.equiv 및 $HOME/.rhosts 파일 권한이 600 이하인 경우 3. /etc/hosts.equiv 및 $HOME/.rhosts 파일 설정에 “+” 설정이 없는 경우 취약: rlogin, rsh, rexec 서비스를 사용하며 아래와 같은 설정이 적용되지 않은 경우 1. /etc/hosts.equiv 및 $HOME/.rhosts 파일 소유자가 root 또는 해당 계정이 아닌 경우 2. /etc/hosts.equiv 및 $HOME/.rhosts 파일 권한이 600을 초과한 경우 3. /etc/hosts.equiv 및 $HOME/.rhosts 파일 설정에 “+” 설정이 존재하는 경우 | F32: =_xlfn.XLOOKUP('2-2. 요약 진단결과(Unix)'!F32, '2-2. 요약 진단결과(Unix)'!$F$6:$F$72, '2-2. 요약 진단결과(Unix)'!$F$6:$F$72) -> 양호
C33: U-28 | D33: 접속 IP 및 포트 제한 | E33: 양호: 접속을 허용할 특정 호스트에 대한 IP주소 및 포트 제한을 설정한 경우 취약: 접속을 허용할 특정 호스트에 대한 IP주소 및 포트 제한을 설정하지 않은 경우 | F33: =_xlfn.XLOOKUP('2-2. 요약 진단결과(Unix)'!F33, '2-2. 요약 진단결과(Unix)'!$F$6:$F$72, '2-2. 요약 진단결과(Unix)'!$F$6:$F$72) -> 양호
C34: U-29 | D34: hosts.lpd 파일 소유자 및 권한 설정 | E34: 양호: /etc/hosts.lpd 파일이 존재하지 않거나, 불가피하게 사용 시 /etc/hosts.lpd 파일의 소유자가 root이고, 권한이 600 이하인 경우 취약: /etc/hosts.lpd 파일이 존재하며, 파일의 소유자가 root가 아니거나, 권한이 600 이하가 아닌 경우 | F34: =_xlfn.XLOOKUP('2-2. 요약 진단결과(Unix)'!F34, '2-2. 요약 진단결과(Unix)'!$F$6:$F$72, '2-2. 요약 진단결과(Unix)'!$F$6:$F$72) -> 양호
C35: U-30 | D35: UMASK 설정 관리 | E35: 양호: UMASK 값이 022 이상으로 설정된 경우 취약: UMASK 값이 022 미만으로 설정된 경우 | F35: =_xlfn.XLOOKUP('2-2. 요약 진단결과(Unix)'!F35, '2-2. 요약 진단결과(Unix)'!$F$6:$F$72, '2-2. 요약 진단결과(Unix)'!$F$6:$F$72) -> 양호 | G35: profile 내에는 UMASK 값이 미존재
C36: U-31 | D36: 홈 디렉토리 소유자 및 권한 설정 | E36: 양호: 홈 디렉토리 소유자가 해당 계정이고, 타 사용자 쓰기 권한이 제거된 경우 취약: 홈 디렉토리 소유자가 해당 계정이 아니거나, 타 사용자 쓰기 권한이 부여된 경우 | F36: =_xlfn.XLOOKUP('2-2. 요약 진단결과(Unix)'!F36, '2-2. 요약 진단결과(Unix)'!$F$6:$F$72, '2-2. 요약 진단결과(Unix)'!$F$6:$F$72) -> 양호
C37: U-32 | D37: 홈 디렉토리로 지정한 디렉토리의 존재 관리 | E37: 양호: 홈 디렉토리가 존재하지 않는 계정이 발견되지 않는 경우 취약: 홈 디렉토리가 존재하지 않는 계정이 발견된 경우 | F37: =_xlfn.XLOOKUP('2-2. 요약 진단결과(Unix)'!F37, '2-2. 요약 진단결과(Unix)'!$F$6:$F$72, '2-2. 요약 진단결과(Unix)'!$F$6:$F$72) -> 양호
C38: U-33 | D38: 숨겨진 파일 및 디렉토리 검색 및 제거 | E38: 양호: 불필요하거나 의심스러운 숨겨진 파일 및 디렉토리를 제거한 경우 취약: 불필요하거나 의심스러운 숨겨진 파일 및 디렉토리를 제거하지 않은 경우 | F38: =_xlfn.XLOOKUP('2-2. 요약 진단결과(Unix)'!F38, '2-2. 요약 진단결과(Unix)'!$F$6:$F$72, '2-2. 요약 진단결과(Unix)'!$F$6:$F$72) -> 양호
B39: 3. 서비스 관리 | C39: U-34 | D39: Finger 서비스 비활성화 | E39: 양호: Finger 서비스가 비활성화된 경우 취약: Finger 서비스가 활성화된 경우 | F39: =_xlfn.XLOOKUP('2-2. 요약 진단결과(Unix)'!F39, '2-2. 요약 진단결과(Unix)'!$F$6:$F$72, '2-2. 요약 진단결과(Unix)'!$F$6:$F$72) -> 양호
C40: U-35 | D40: 공유 서비스에 대한 익명 접근 제한 설정 | E40: 양호: 공유 서비스에 대해 익명 접근을 제한한 경우 취약: 공유 서비스에 대해 익명 접근을 허용한 경우 | F40: =_xlfn.XLOOKUP('2-2. 요약 진단결과(Unix)'!F40, '2-2. 요약 진단결과(Unix)'!$F$6:$F$72, '2-2. 요약 진단결과(Unix)'!$F$6:$F$72) -> 양호
C41: U-36 | D41: r 계열 서비스 비활성화 | E41: 양호: 불필요한 r 계열 서비스가 비활성화된 경우 취약: 불필요한 r 계열 서비스가 활성화된 경우 | F41: =_xlfn.XLOOKUP('2-2. 요약 진단결과(Unix)'!F41, '2-2. 요약 진단결과(Unix)'!$F$6:$F$72, '2-2. 요약 진단결과(Unix)'!$F$6:$F$72) -> 양호
...
